########## [ file   ] --- test/base.cpp
1/20       [ run    ] pass
           [     OK ] pass (0.0 ms)
2/20       [ run    ] pass2
Hello!
           [     OK ] pass2 (100.7 ms)
3/20       [ run    ] throw_simple
  .        [   .    ]     Uncaught exception:
  .        [   .    ]         std::runtime_error
  .        [   .    ]             heh
  1 failed [   FAIL ] throw_simple (0.1 ms)   at:  test/base.cpp:19
4/20       [ run    ] throw_nested
  .        [   .    ]     Uncaught exception:
  .        [   .    ]         std::logic_error
  .        [   .    ]             while doing stuff:
  .        [   .    ]         std::out_of_range
  .        [   .    ]             while doing more stuff:
  .        [   .    ]             (and another line)
  .        [   .    ]         std::runtime_error
  .        [   .    ]             heh
  .        [   .    ]             this is a
  .        [   .    ]             multiline message
  2 failed [   FAIL ] throw_nested (0.1 ms)   at:  test/base.cpp:24
5/20       [ run    ] throw_unknown
  .        [   .    ]     Uncaught exception:
  .        [   .    ]         Unknown exception.
  3 failed [   FAIL ] throw_unknown (0.0 ms)   at:  test/base.cpp:44
6/20       [ run    ] throw_nested_unknown
  .        [   .    ]     Uncaught exception:
  .        [   .    ]         std::logic_error
  .        [   .    ]             while doing stuff:
  .        [   .    ]         Unknown exception.
  4 failed [   FAIL ] throw_nested_unknown (0.1 ms)   at:  test/base.cpp:49
7/20       [ run    ] throw_interrupt
  4 failed [     OK ] throw_interrupt (0.0 ms)
8/20       [ run    ] assert_false
Before!
  .        [   .    ]     Assertion failed at:  test/base.cpp:73
  .        [   .    ]         Expression:  FALSEY
  .        [   .    ]         Evaluated to false.
After soft assertion!
  .        [   .    ]     Assertion failed at:  test/base.cpp:75
  .        [   .    ]         Expression:  false
  .        [   .    ]         Evaluated to false.
  5 failed [   FAIL ] assert_false (0.1 ms)   at:  test/base.cpp:70
9/20       [ run    ] assert_throws
Before!
  .        [   .    ]     Assertion failed at:  test/base.cpp:83
  .        [   .    ]         Expression:  throw std::runtime_error("huh"), true
  .        [   .    ]         Threw an uncaught exception:
  .        [   .    ]             std::runtime_error
  .        [   .    ]                 huh
After soft assertion!
  .        [   .    ]     Assertion failed at:  test/base.cpp:85
  .        [   .    ]         Expression:  throw std::runtime_error("huh"), true
  .        [   .    ]         Threw an uncaught exception:
  .        [   .    ]             std::runtime_error
  .        [   .    ]                 huh
  6 failed [   FAIL ] assert_throws (0.0 ms)   at:  test/base.cpp:80
10/20      [ run    ] assert_throws_unknown
  .        [   .    ]     Assertion failed at:  test/base.cpp:91
  .        [   .    ]         Expression:  throw 42, true
  .        [   .    ]         Threw an uncaught exception:
  .        [   .    ]             Unknown exception.
  7 failed [   FAIL ] assert_throws_unknown (0.0 ms)   at:  test/base.cpp:89
11/20      [ run    ] must_throw_any_fail
Before!
  .        [   .    ]     Missing exception at:  test/base.cpp:98
  .        [   .    ]         Expression:  42
After soft check!
  .        [   .    ]     Missing exception at:  test/base.cpp:100
  .        [   .    ]         Expression:  42
  8 failed [   FAIL ] must_throw_any_fail (0.0 ms)   at:  test/base.cpp:95
12/20      [ run    ] must_throw_fail
Before!
  .        [   .    ]     Missing exception at:  test/base.cpp:108
  .        [   .    ]         Expression:  42
After soft check!
  .        [   .    ]     Missing exception at:  test/base.cpp:110
  .        [   .    ]         Expression:  42
  9 failed [   FAIL ] must_throw_fail (0.0 ms)   at:  test/base.cpp:105
13/20      [ run    ] must_throw_any_unknown
  9 failed [     OK ] must_throw_any_unknown (0.0 ms)
14/20      [ run    ] must_throw_any
  9 failed [     OK ] must_throw_any (0.0 ms)
15/20      [ run    ] must_throw_mismatch_unknown
Before!
  .        [   .    ]     Incorrect exception at:  test/base.cpp:130
  .        [   .    ]         Expression:  throw 42
  .        [   .    ]         Exception:
  .        [   .    ]             Caught    | Expected
  .        [   .    ]             (unknown) # std::runtime_error
  .        [   .    ]                .      #     42
After soft check!
  .        [   .    ]     Incorrect exception at:  test/base.cpp:132
  .        [   .    ]         Expression:  throw 42
  .        [   .    ]         Exception:
  .        [   .    ]             Caught    | Expected
  .        [   .    ]             (unknown) # std::runtime_error
  .        [   .    ]                .      #     42
  .        [   .    ]                .      #     hello world
 10 failed [   FAIL ] must_throw_mismatch_unknown (0.1 ms)   at:  test/base.cpp:127
16/20      [ run    ] must_throw_mismatch_type
Before!
  .        [   .    ]     Incorrect exception at:  test/base.cpp:140
  .        [   .    ]         Expression:  throw std::logic_error("foo\nbarbar")
  .        [   .    ]         Exception:
  .        [   .    ]             Caught           | Expected
  .        [   .    ]             std::logic_error # std::runtime_error
  .        [   .    ]                 foo          |     foo
  .        [   .    ]                 barbar       |     barbar
After soft check!
  .        [   .    ]     Incorrect exception at:  test/base.cpp:142
  .        [   .    ]         Expression:  throw std::logic_error("some long long message\nbarbar")
  .        [   .    ]         Exception:
  .        [   .    ]             Caught                     | Expected
  .        [   .    ]             std::logic_error           # std::runtime_error
  .        [   .    ]                 some long long message |     some long long message
  .        [   .    ]                 barbar                 |     barbar
 11 failed [   FAIL ] must_throw_mismatch_type (0.1 ms)   at:  test/base.cpp:137
17/20      [ run    ] must_throw_mismatch_message
Before!
  .        [   .    ]     Incorrect exception at:  test/base.cpp:150
  .        [   .    ]         Expression:  throw std::logic_error("foo\nbarbar1")
  .        [   .    ]         Exception:
  .        [   .    ]             Caught           | Expected
  .        [   .    ]             std::logic_error # std::runtime_error
  .        [   .    ]                 foo          |     foo
  .        [   .    ]                 barbar1      #     barbar
  .        [   .    ]     Incorrect exception at:  test/base.cpp:152
  .        [   .    ]         Expression:  throw std::logic_error("foo\nbarbar\nhmm")
  .        [   .    ]         Exception:
  .        [   .    ]             Caught           | Expected
  .        [   .    ]             std::logic_error # std::runtime_error
  .        [   .    ]                 foo          |     foo
  .        [   .    ]                 barbar       |     barbar
  .        [   .    ]                 hmm          #    .
  .        [   .    ]     Incorrect exception at:  test/base.cpp:154
  .        [   .    ]         Expression:  throw std::logic_error("foo\nbarbar")
  .        [   .    ]         Exception:
  .        [   .    ]             Caught           | Expected
  .        [   .    ]             std::logic_error # std::runtime_error
  .        [   .    ]                 foo          |     foo
  .        [   .    ]                 barbar       |     barbar
  .        [   .    ]                .             #     hmm
After soft check!
  .        [   .    ]     Incorrect exception at:  test/base.cpp:156
  .        [   .    ]         Expression:  throw std::logic_error("some long long message1\nbarbar")
  .        [   .    ]         Exception:
  .        [   .    ]             Caught                      | Expected
  .        [   .    ]             std::logic_error            # std::runtime_error
  .        [   .    ]                 some long long message1 #     some long long message
  .        [   .    ]                 barbar                  |     barbar
 12 failed [   FAIL ] must_throw_mismatch_message (0.1 ms)   at:  test/base.cpp:147
18/20      [ run    ] must_throw_mismatch_message_only
  .        [   .    ]     Incorrect exception at:  test/base.cpp:163
  .        [   .    ]         Expression:  throw std::runtime_error("blah")
  .        [   .    ]         Exception:
  .        [   .    ]             Caught:   blah
  .        [   .    ]             Expected: bleh
  .        [   .    ]     Incorrect exception at:  test/base.cpp:164
  .        [   .    ]         Expression:  throw std::runtime_error("blah\nfoo")
  .        [   .    ]         Exception:
  .        [   .    ]             Caught:   blah
  .        [   .    ]                       foo
  .        [   .    ]             Expected: bleh
  .        [   .    ]     Incorrect exception at:  test/base.cpp:165
  .        [   .    ]         Expression:  throw std::runtime_error("blah")
  .        [   .    ]         Exception:
  .        [   .    ]             Caught:   blah
  .        [   .    ]             Expected: bleh
  .        [   .    ]                       foo
 13 failed [   FAIL ] must_throw_mismatch_message_only (0.1 ms)   at:  test/base.cpp:161
19/20      [ run    ] must_throw_mismatch_nested
  .        [   .    ]     Incorrect exception at:  test/base.cpp:181
  .        [   .    ]         Expression:  try { throw std::runtime_error("blah"); } catch (...) { std::throw_with_nested(std::logic_error("logic")); }
  .        [   .    ]         Exception:
  .        [   .    ]             Caught             | Expected
  .        [   .    ]             std::logic_error   | std::logic_error
  .        [   .    ]                 logic          |     logic
  .        [   .    ]             std::runtime_error # (none)
  .        [   .    ]                 blah           #    .
  .        [   .    ]     Incorrect exception at:  test/base.cpp:193
  .        [   .    ]         Expression:  try { throw 42; } catch (...) { std::throw_with_nested(std::logic_error("logic")); }
  .        [   .    ]         Exception:
  .        [   .    ]             Caught           | Expected
  .        [   .    ]             std::logic_error | std::logic_error
  .        [   .    ]                 logic        |     logic
  .        [   .    ]             (unknown)        # (none)
  .        [   .    ]                .             #    .
  .        [   .    ]     Incorrect exception at:  test/base.cpp:198
  .        [   .    ]         Expression:  throw std::runtime_error("blah");
  .        [   .    ]         Exception:
  .        [   .    ]             Caught             | Expected
  .        [   .    ]             std::runtime_error | std::runtime_error
  .        [   .    ]                 blah           |     blah
  .        [   .    ]             (none)             # std::runtime_error
  .        [   .    ]                .               #     bleh
  .        [   .    ]     Incorrect exception at:  test/base.cpp:210
  .        [   .    ]         Expression:  try { throw std::runtime_error("blah"); } catch (...) { std::throw_with_nested(std::logic_error("logic1")); }
  .        [   .    ]         Exception:
  .        [   .    ]             Caught             | Expected
  .        [   .    ]             std::logic_error   | std::logic_error
  .        [   .    ]                 logic1         #     logic
  .        [   .    ]             std::runtime_error | std::runtime_error
  .        [   .    ]                 blah           |     blah
 14 failed [   FAIL ] must_throw_mismatch_nested (0.2 ms)   at:  test/base.cpp:169
20/20      [ run    ] must_throw_pass_nested
 14 failed [     OK ] must_throw_pass_nested (0.0 ms)

Failed tests:
    throw_simple                       at:  test/base.cpp:19
    throw_nested                       at:  test/base.cpp:24
    throw_unknown                      at:  test/base.cpp:44
    throw_nested_unknown               at:  test/base.cpp:49
    assert_false                       at:  test/base.cpp:70
    assert_throws                      at:  test/base.cpp:80
    assert_throws_unknown              at:  test/base.cpp:89
    must_throw_any_fail                at:  test/base.cpp:95
    must_throw_fail                    at:  test/base.cpp:105
    must_throw_mismatch_unknown        at:  test/base.cpp:127
    must_throw_mismatch_type           at:  test/base.cpp:137
    must_throw_mismatch_message        at:  test/base.cpp:147
    must_throw_mismatch_message_only   at:  test/base.cpp:161
    must_throw_mismatch_nested         at:  test/base.cpp:169

Ran 20 tests, 6 passed, 14 FAILED
--- EXIT CODE 1
